INFO:numba.cuda.cudadrv.driver:init
DEBUG:numba.cuda.cudadrv.driver:call driver api: cuInit
ERROR:numba.cuda.cudadrv.driver:Call to cuInit results in CUDA_ERROR_NO_DEVICE
INFO:numba.cuda.cudadrv.driver:init
DEBUG:numba.cuda.cudadrv.driver:call driver api: cuInit
ERROR:numba.cuda.cudadrv.driver:Call to cuInit results in CUDA_ERROR_NO_DEVICE
INFO:numba.cuda.cudadrv.driver:init
DEBUG:numba.cuda.cudadrv.driver:call driver api: cuInit
ERROR:numba.cuda.cudadrv.driver:Call to cuInit results in CUDA_ERROR_NO_DEVICE
INFO:numba.cuda.cudadrv.driver:init
DEBUG:numba.cuda.cudadrv.driver:call driver api: cuInit
ERROR:numba.cuda.cudadrv.driver:Call to cuInit results in CUDA_ERROR_NO_DEVICE
INFO:numba.cuda.cudadrv.driver:init
INFO:numba.cuda.cudadrv.driver:init
DEBUG:numba.cuda.cudadrv.driver:call driver api: cuInit
DEBUG:numba.cuda.cudadrv.driver:call driver api: cuInit
ERROR:numba.cuda.cudadrv.driver:Call to cuInit results in CUDA_ERROR_NO_DEVICE
ERROR:numba.cuda.cudadrv.driver:Call to cuInit results in CUDA_ERROR_NO_DEVICE
ERROR:root:##### Exception in random_search_runner:
No samples will be generated with the provided ratio settings.

Traceback (most recent call last):
  File "/project/6047694/tvhahn/feat-store/src/models/train.py", line 360, in random_search_runner
    ) = train_single_model(
  File "/project/6047694/tvhahn/feat-store/src/models/train.py", line 299, in train_single_model
    model_metrics_dict, feat_col_list = kfold_cv(
  File "/project/6047694/tvhahn/feat-store/src/models/train.py", line 149, in kfold_cv
    x_train, y_train = under_over_sampler(
  File "/project/6047694/tvhahn/feat-store/src/models/utils.py", line 82, in under_over_sampler
    x_resampled, y_resampled = ADASYN(
  File "/home/tvhahn/featstore/lib/python3.8/site-packages/imblearn/base.py", line 83, in fit_resample
    output = self._fit_resample(X, y)
  File "/home/tvhahn/featstore/lib/python3.8/site-packages/imblearn/over_sampling/_adasyn.py", line 147, in _fit_resample
    raise ValueError(
ValueError: No samples will be generated with the provided ratio settings.
ERROR:root:##### Exception in random_search_runner:
No samples will be generated with the provided ratio settings.

Traceback (most recent call last):
  File "/project/6047694/tvhahn/feat-store/src/models/train.py", line 360, in random_search_runner
    ) = train_single_model(
  File "/project/6047694/tvhahn/feat-store/src/models/train.py", line 299, in train_single_model
    model_metrics_dict, feat_col_list = kfold_cv(
  File "/project/6047694/tvhahn/feat-store/src/models/train.py", line 149, in kfold_cv
    x_train, y_train = under_over_sampler(
  File "/project/6047694/tvhahn/feat-store/src/models/utils.py", line 82, in under_over_sampler
    x_resampled, y_resampled = ADASYN(
  File "/home/tvhahn/featstore/lib/python3.8/site-packages/imblearn/base.py", line 83, in fit_resample
    output = self._fit_resample(X, y)
  File "/home/tvhahn/featstore/lib/python3.8/site-packages/imblearn/over_sampling/_adasyn.py", line 147, in _fit_resample
    raise ValueError(
ValueError: No samples will be generated with the provided ratio settings.
ERROR:root:##### Exception in random_search_runner:
No samples will be generated with the provided ratio settings.

Traceback (most recent call last):
  File "/project/6047694/tvhahn/feat-store/src/models/train.py", line 360, in random_search_runner
    ) = train_single_model(
  File "/project/6047694/tvhahn/feat-store/src/models/train.py", line 299, in train_single_model
    model_metrics_dict, feat_col_list = kfold_cv(
  File "/project/6047694/tvhahn/feat-store/src/models/train.py", line 149, in kfold_cv
    x_train, y_train = under_over_sampler(
  File "/project/6047694/tvhahn/feat-store/src/models/utils.py", line 82, in under_over_sampler
    x_resampled, y_resampled = ADASYN(
  File "/home/tvhahn/featstore/lib/python3.8/site-packages/imblearn/base.py", line 83, in fit_resample
    output = self._fit_resample(X, y)
  File "/home/tvhahn/featstore/lib/python3.8/site-packages/imblearn/over_sampling/_adasyn.py", line 147, in _fit_resample
    raise ValueError(
ValueError: No samples will be generated with the provided ratio settings.
ERROR:root:##### Exception in random_search_runner:
No samples will be generated with the provided ratio settings.

Traceback (most recent call last):
  File "/project/6047694/tvhahn/feat-store/src/models/train.py", line 360, in random_search_runner
    ) = train_single_model(
  File "/project/6047694/tvhahn/feat-store/src/models/train.py", line 299, in train_single_model
    model_metrics_dict, feat_col_list = kfold_cv(
  File "/project/6047694/tvhahn/feat-store/src/models/train.py", line 149, in kfold_cv
    x_train, y_train = under_over_sampler(
  File "/project/6047694/tvhahn/feat-store/src/models/utils.py", line 82, in under_over_sampler
    x_resampled, y_resampled = ADASYN(
  File "/home/tvhahn/featstore/lib/python3.8/site-packages/imblearn/base.py", line 83, in fit_resample
    output = self._fit_resample(X, y)
  File "/home/tvhahn/featstore/lib/python3.8/site-packages/imblearn/over_sampling/_adasyn.py", line 147, in _fit_resample
    raise ValueError(
ValueError: No samples will be generated with the provided ratio settings.
ERROR:root:##### Exception in random_search_runner:
No samples will be generated with the provided ratio settings.

Traceback (most recent call last):
  File "/project/6047694/tvhahn/feat-store/src/models/train.py", line 360, in random_search_runner
    ) = train_single_model(
  File "/project/6047694/tvhahn/feat-store/src/models/train.py", line 299, in train_single_model
    model_metrics_dict, feat_col_list = kfold_cv(
  File "/project/6047694/tvhahn/feat-store/src/models/train.py", line 149, in kfold_cv
    x_train, y_train = under_over_sampler(
  File "/project/6047694/tvhahn/feat-store/src/models/utils.py", line 82, in under_over_sampler
    x_resampled, y_resampled = ADASYN(
  File "/home/tvhahn/featstore/lib/python3.8/site-packages/imblearn/base.py", line 83, in fit_resample
    output = self._fit_resample(X, y)
  File "/home/tvhahn/featstore/lib/python3.8/site-packages/imblearn/over_sampling/_adasyn.py", line 147, in _fit_resample
    raise ValueError(
ValueError: No samples will be generated with the provided ratio settings.
ERROR:root:##### Exception in random_search_runner:
No samples will be generated with the provided ratio settings.

Traceback (most recent call last):
  File "/project/6047694/tvhahn/feat-store/src/models/train.py", line 360, in random_search_runner
    ) = train_single_model(
  File "/project/6047694/tvhahn/feat-store/src/models/train.py", line 299, in train_single_model
    model_metrics_dict, feat_col_list = kfold_cv(
  File "/project/6047694/tvhahn/feat-store/src/models/train.py", line 149, in kfold_cv
    x_train, y_train = under_over_sampler(
  File "/project/6047694/tvhahn/feat-store/src/models/utils.py", line 82, in under_over_sampler
    x_resampled, y_resampled = ADASYN(
  File "/home/tvhahn/featstore/lib/python3.8/site-packages/imblearn/base.py", line 83, in fit_resample
    output = self._fit_resample(X, y)
  File "/home/tvhahn/featstore/lib/python3.8/site-packages/imblearn/over_sampling/_adasyn.py", line 147, in _fit_resample
    raise ValueError(
ValueError: No samples will be generated with the provided ratio settings.
ERROR:root:##### Exception in random_search_runner:
No samples will be generated with the provided ratio settings.

Traceback (most recent call last):
  File "/project/6047694/tvhahn/feat-store/src/models/train.py", line 360, in random_search_runner
    ) = train_single_model(
  File "/project/6047694/tvhahn/feat-store/src/models/train.py", line 299, in train_single_model
    model_metrics_dict, feat_col_list = kfold_cv(
  File "/project/6047694/tvhahn/feat-store/src/models/train.py", line 149, in kfold_cv
    x_train, y_train = under_over_sampler(
  File "/project/6047694/tvhahn/feat-store/src/models/utils.py", line 82, in under_over_sampler
    x_resampled, y_resampled = ADASYN(
  File "/home/tvhahn/featstore/lib/python3.8/site-packages/imblearn/base.py", line 83, in fit_resample
    output = self._fit_resample(X, y)
  File "/home/tvhahn/featstore/lib/python3.8/site-packages/imblearn/over_sampling/_adasyn.py", line 147, in _fit_resample
    raise ValueError(
ValueError: No samples will be generated with the provided ratio settings.
